Workbook

Sheet README
A1: Physics History Experiments — Research Workbook
A3: Scope note
A4: This workbook is a curated, research-oriented catalogue of major experiments and observations in the history of physics. It is not a claim that there exists a universally agreed finite list of all important experiments. The catalogue emphasizes experiments that created, rejected, or decisively constrained major theoretical frameworks; enabled new measurement regimes; or opened major fields of research.
A10: Workbook structure
A11: Experiments | B11: Main catalogue; one row per experiment/observational milestone with source URL.
A12: Summary | B12: Counts by branch, tier, and period for orientation.
A13: Bibliography | B13: General reference starting points and source-selection guidance.
A14: Glossary | B14: Field values and tier definitions used in the workbook.
A15: Importance tier 1 | B15: Canonical field-shaping experiment/observation.
A16: Importance tier 2 | B16: Very important but more specialized, programmatic, or partly derivative.
A17: Importance tier 3 | B17: Contextual/theoretical/instrumental milestone included for completeness.
A19: Recommended scholarly workflow
A20: Use this sheet as a structured starting corpus. For publication-grade historical work, verify each row against original papers, laboratory notebooks where available, Nobel lectures, institutional archives, and modern historiography. The Source URL column prioritizes stable overview pages and institutional reference points rather than attempting to replace primary-source bibliography.

Sheet Experiments
A1: ID | B1: Year / period | C1: Experiment or observation | D1: Lead experimenter(s) | E1: Location / institution | F1: Physics branch | G1: Subfield | H1: Apparatus / method | I1: Measured / observed quantity | J1: Key finding | K1: Theory / concept tested or established | L1: Historical significance | M1: Source kind | N1: Source URL | O1: Importance tier | P1: Notes / caveats
A2: E001 | B2: c. 240 BCE | C2: Eratosthenes' measurement of Earth circumference | D2: Eratosthenes | E2: Alexandria and Syene | F2: Astronomy / geophysics | G2: geodesy | H2: Solar shadow angles at two latitudes | I2: Solar zenith angle; baseline distance | J2: Estimated Earth's circumference from angular geometry | K2: Spherical Earth; quantitative astronomy | L2: Foundational quantitative geophysical measurement | M2: Encyclopedic overview | N2: https://en.wikipedia.org/wiki/Eratosthenes#Measurement_of_Earth%27s_circumference | O2: 1 | P2: Astronomical observation rather than controlled laboratory experiment
A3: E002 | B3: c. 250 BCE | C3: Archimedes' buoyancy investigations | D3: Archimedes | E3: Syracuse | F3: Fluid mechanics | G3: hydrostatics | H3: Immersion and displacement reasoning | I3: Displaced volume; apparent weight | J3: Principle of buoyancy and specific gravity reasoning | K3: Hydrostatic equilibrium | L3: Foundational to hydrostatics and density measurement | M3: Encyclopedic overview | N3: https://en.wikipedia.org/wiki/Archimedes%27_principle | O3: 1 | P3: Crown story is partly legendary; principle is robust
A4: E003 | B4: c. 1021 | C4: Ibn al-Haytham's camera obscura / optics experiments | D4: Ibn al-Haytham | E4: Basra / Cairo intellectual tradition | F4: Optics | G4: geometrical optics | H4: Dark chamber, apertures, controlled light paths | I4: Image formation; rectilinear propagation | J4: Light travels in straight lines; vision involves light entering the eye | K4: Experimental optics and visual perception | L4: Major early example of controlled optical experimentation | M4: Encyclopedic overview | N4: https://en.wikipedia.org/wiki/Book_of_Optics | O4: 1 | P4: Dates approximate
A5: E004 | B5: 1586 | C5: Stevin's inclined-plane / hydrostatic demonstrations | D5: Simon Stevin | E5: Low Countries | F5: Classical mechanics | G5: statics | H5: Chain on triangular inclined plane; hydrostatic paradox demonstrations | I5: Forces on inclined planes and fluids | J5: Resolved statics of inclined planes; hydrostatic pressure ideas | K5: Statics; virtual work precursors | L5: Important pre-Newtonian mechanics result | M5: Encyclopedic overview | N5: https://en.wikipedia.org/wiki/Simon_Stevin | O5: 2 | P5: Multiple demonstrations rather than one single experiment
A6: E005 | B6: 1602-1604 | C6: Galileo's inclined-plane acceleration experiments | D6: Galileo Galilei | E6: Padua | F6: Classical mechanics | G6: kinematics | H6: Bronze balls on inclined planes; timing by water clock | I6: Distance vs. time; acceleration | J6: Uniform acceleration and quadratic distance-time relation | K6: Mathematical law of free fall | L6: Canonical birth of quantitative experimental mechanics | M6: Scholarly overview | N6: https://en.wikipedia.org/wiki/Galileo%27s_inclined_plane_experiment | O6: 1 | P6: Historical reconstruction debated in detail
A7: E006 | B7: c. 1602 | C7: Galileo's pendulum observations | D7: Galileo Galilei | E7: Pisa / Padua | F7: Classical mechanics | G7: oscillations | H7: Pendula of different amplitudes and lengths | I7: Period dependence | J7: Near-isochronism for small oscillations; period tied to length | K7: Periodic motion | L7: Important precursor to precision timekeeping and oscillator physics | M7: Encyclopedic overview | N7: https://en.wikipedia.org/wiki/Pendulum#History | O7: 2 | P7: Some details come from later accounts
A8: E007 | B8: 1643 | C8: Torricelli's barometer experiment | D8: Evangelista Torricelli | E8: Florence | F8: Fluid mechanics / atmospheric physics | G8: pressure | H8: Mercury column sealed tube inverted in a basin | I8: Column height; vacuum space | J8: Atmospheric pressure supports mercury column; artificial vacuum exists | K8: Atmospheric pressure; vacuum | L8: Overturned horror vacui and founded barometry | M8: Encyclopedic overview | N8: https://en.wikipedia.org/wiki/Barometer#History | O8: 1
A9: E008 | B9: 1648 | C9: Pascal's Puy de Dôme barometric test | D9: Blaise Pascal; Florin Périer | E9: Puy de Dôme, France | F9: Fluid mechanics / atmospheric physics | G9: pressure | H9: Barometer readings at different altitude | I9: Mercury column height vs altitude | J9: Atmospheric pressure decreases with altitude | K9: Atmospheric pressure as weight of air | L9: Strong early field test of atmospheric pressure theory | M9: Encyclopedic overview | N9: https://en.wikipedia.org/wiki/Blaise_Pascal#Fluid_dynamics | O9: 1
A10: E009 | B10: 1654 | C10: Magdeburg hemispheres vacuum demonstration | D10: Otto von Guericke | E10: Regensburg / Magdeburg | F10: Fluid mechanics | G10: vacuum / pressure | H10: Evacuated copper hemispheres pulled by horses | I10: Force due to external air pressure | J10: Atmospheric pressure can exert enormous force | K10: Vacuum physics; air pressure | L10: Iconic demonstration of vacuum and atmospheric pressure | M10: Encyclopedic overview | N10: https://en.wikipedia.org/wiki/Magdeburg_hemispheres | O10: 2 | P10: Public demonstration, not precision measurement
A11: E010 | B11: 1662 | C11: Boyle's air-pump pressure-volume experiments | D11: Robert Boyle; Robert Hooke | E11: Oxford | F11: Thermodynamics / gases | G11: gas laws | H11: Air pump and J-shaped glass tubes | I11: Pressure and volume of air | J11: Pressure inversely proportional to volume at constant temperature | K11: Boyle's law | L11: Foundation of quantitative gas laws | M11: Primary / historical overview | N11: https://en.wikipedia.org/wiki/Boyle%27s_law | O11: 1 | P11: Often cited as 1662 publication of Boyle's law
A12: E011 | B12: 1666 | C12: Newton's prism decomposition of white light | D12: Isaac Newton | E12: Cambridge | F12: Optics | G12: dispersion | H12: Prisms, apertures, darkened room | I12: Angular separation of colors | J12: White light is composite; colors have different refrangibility | K12: Dispersion; color theory | L12: Foundational experiment in physical optics | M12: Encyclopedic overview | N12: https://en.wikipedia.org/wiki/Newton%27s_prism_experiment | O12: 1
A13: E012 | B13: 1672 | C13: Newton's rings interference observation | D13: Isaac Newton | E13: Cambridge | F13: Optics | G13: interference | H13: Plano-convex lens on flat glass | I13: Concentric colored fringes | J13: Thin-film interference pattern observed | K13: Wave optics phenomenon, despite Newton's corpuscular interpretation | L13: Important evidence later reinterpreted by wave theory | M13: Encyclopedic overview | N13: https://en.wikipedia.org/wiki/Newton%27s_rings | O13: 2
A14: E013 | B14: 1676 | C14: Rømer's astronomical estimate of light speed | D14: Ole Rømer | E14: Paris Observatory | F14: Optics / astronomy | G14: speed of light | H14: Timing eclipses of Jupiter's moon Io | I14: Delay in eclipse timings | J14: Light has finite propagation speed | K14: Finite speed of light | L14: First successful quantitative evidence for finite light speed | M14: Encyclopedic overview | N14: https://en.wikipedia.org/wiki/R%C3%B8mer%27s_determination_of_the_speed_of_light | O14: 1 | P14: Astronomical observation
A15: E014 | B15: 1728 | C15: Bradley's stellar aberration measurement | D15: James Bradley | E15: England | F15: Astronomy / relativity precursor | G15: stellar aberration | H15: Precision telescopic observations | I15: Annual displacement of stellar positions | J15: Stellar aberration caused by Earth's orbital velocity and finite light speed | K15: Light propagation; heliocentrism | L15: Important confirmation of Earth's motion and finite light speed | M15: Encyclopedic overview | N15: https://en.wikipedia.org/wiki/Aberration_(astronomy) | O15: 1
A16: E015 | B16: 1738 | C16: Bernoulli kinetic theory arguments from gas behavior | D16: Daniel Bernoulli | E16: Basel / St. Petersburg tradition | F16: Thermodynamics | G16: kinetic theory | H16: Theoretical analysis informed by gas-pressure observations | I16: Pressure; particle motion model | J16: Gas pressure interpretable via molecular motion | K16: Kinetic theory of gases | L16: Conceptual precursor rather than a single experiment | M16: Encyclopedic overview | N16: https://en.wikipedia.org/wiki/Kinetic_theory_of_gases#History | O16: 3 | P16: Included for context; not a discrete experiment
A17: E016 | B17: 1752 | C17: Franklin's kite experiment and lightning electricity | D17: Benjamin Franklin | E17: Philadelphia | F17: Electromagnetism | G17: electrostatics | H17: Kite, wet string, key, Leyden jar | I17: Charge transfer from storm cloud | J17: Lightning is electrical | K17: Atmospheric electricity | L17: Iconic demonstration linking lightning and electricity | M17: Encyclopedic overview | N17: https://en.wikipedia.org/wiki/Kite_experiment | O17: 2 | P17: Historicity and risk details are debated
A18: E017 | B18: 1785 | C18: Coulomb torsion-balance experiments | D18: Charles-Augustin de Coulomb | E18: Paris | F18: Electromagnetism | G18: electrostatics / magnetostatics | H18: Torsion balance | I18: Force vs charge/distance | J18: Inverse-square electrostatic force law | K18: Coulomb's law | L18: Quantified electrostatic interaction | M18: Encyclopedic overview | N18: https://en.wikipedia.org/wiki/Coulomb%27s_law | O18: 1
A19: E018 | B19: 1787 | C19: Chladni figures | D19: Ernst Chladni | E19: Germany | F19: Acoustics / waves | G19: vibrations | H19: Sand on vibrating plates | I19: Nodal-line patterns | J19: Vibrating plates form characteristic mode patterns | K19: Normal modes; wave interference | L19: Founded experimental study of acoustical modes | M19: Encyclopedic overview | N19: https://en.wikipedia.org/wiki/Chladni_figures | O19: 2
A20: E019 | B20: 1798 | C20: Cavendish torsion-balance measurement of gravitational attraction | D20: Henry Cavendish | E20: Clapham, London | F20: Gravitation | G20: precision measurement | H20: Torsion balance with lead spheres | I20: Tiny gravitational torque; Earth density | J20: Measured Newtonian gravitational attraction in laboratory; inferred Earth density | K20: Newtonian gravitation; gravitational constant precursor | L20: Canonical precision test of universal gravitation | M20: Encyclopedic overview | N20: https://en.wikipedia.org/wiki/Cavendish_experiment | O20: 1 | P20: Cavendish reported Earth density; G later derived
A21: E020 | B21: 1798 | C21: Rumford cannon-boring heat experiment | D21: Benjamin Thompson, Count Rumford | E21: Munich | F21: Thermodynamics | G21: heat theory | H21: Cannon boring with dull drill; water heating | I21: Heat produced by mechanical work | J21: Heat is associated with motion/work, challenging caloric theory | K21: Mechanical equivalent of heat precursor | L21: Key step toward energy conservation and thermodynamics | M21: Encyclopedic overview | N21: https://en.wikipedia.org/wiki/Benjamin_Thompson#Experiments_with_heat | O21: 1
A22: E021 | B22: 1801 | C22: Young's double-slit interference experiment | D22: Thomas Young | E22: Royal Institution / London | F22: Optics | G22: interference | H22: Two slits / apertures illuminated by light | I22: Fringe pattern | J22: Light exhibits interference consistent with waves | K22: Wave theory of light | L22: Canonical demonstration of wave nature of light | M22: Encyclopedic overview | N22: https://en.wikipedia.org/wiki/Double-slit_experiment | O22: 1
A23: E022 | B23: 1808 | C23: Malus polarization by reflection | D23: Étienne-Louis Malus | E23: Paris | F23: Optics | G23: polarization | H23: Calcite and reflected light observations | I23: Intensity vs orientation | J23: Reflected light can be polarized | K23: Polarization of light | L23: Opened systematic study of polarization | M23: Encyclopedic overview | N23: https://en.wikipedia.org/wiki/Polarization_(waves)#History | O23: 2
A24: E023 | B24: 1815-1819 | C24: Fresnel-Arago interference and polarization experiments | D24: Augustin-Jean Fresnel; François Arago | E24: Paris | F24: Optics | G24: wave optics | H24: Interference setups, diffraction apertures, polarized beams | I24: Diffraction fringes; polarization behavior | J24: Explained diffraction/interference and transverse nature of light waves | K24: Fresnel wave theory | L24: Established wave optics against corpuscular theory | M24: Encyclopedic overview | N24: https://en.wikipedia.org/wiki/Augustin-Jean_Fresnel | O24: 1 | P24: Covers a program of experiments
A25: E024 | B25: 1820 | C25: Ørsted compass-needle deflection by current | D25: Hans Christian Ørsted | E25: Copenhagen | F25: Electromagnetism | G25: electromagnetism | H25: Wire carrying current near compass needle | I25: Magnetic needle deflection | J25: Electric current produces magnetic effect | K25: Link between electricity and magnetism | L25: Launched electromagnetism | M25: Encyclopedic overview | N25: https://en.wikipedia.org/wiki/%C3%98rsted%27s_law | O25: 1
A26: E025 | B26: 1820-1825 | C26: Ampère force experiments between currents | D26: André-Marie Ampère | E26: Paris | F26: Electromagnetism | G26: electrodynamics | H26: Current-carrying wires and balances | I26: Forces between currents | J26: Parallel currents attract/repel depending on direction | K26: Electrodynamic force law | L26: Foundation of mathematical electrodynamics | M26: Encyclopedic overview | N26: https://en.wikipedia.org/wiki/Amp%C3%A8re%27s_force_law | O26: 1
A27: E026 | B27: 1821 | C27: Seebeck thermoelectric effect | D27: Thomas Johann Seebeck | E27: Berlin | F27: Condensed matter / electromagnetism | G27: thermoelectricity | H27: Two dissimilar metals with temperature gradient | I27: Compass deflection / thermoelectric current | J27: Temperature gradients generate electric current in circuits | K27: Thermoelectric effect | L27: Foundation of thermoelectricity and sensors | M27: Encyclopedic overview | N27: https://en.wikipedia.org/wiki/Thermoelectric_effect#Seebeck_effect | O27: 2
A28: E027 | B28: 1827 | C28: Brownian motion observation | D28: Robert Brown | E28: London | F28: Statistical physics | G28: stochastic motion | H28: Microscope observations of pollen particles in water | I28: Irregular particle motion | J28: Suspended particles undergo random motion | K28: Thermal fluctuations; atomic theory later | L28: Key empirical input for statistical mechanics | M28: Encyclopedic overview | N28: https://en.wikipedia.org/wiki/Brownian_motion | O28: 1 | P28: Einstein and Perrin later provided decisive interpretation
A29: E028 | B29: 1831 | C29: Faraday electromagnetic induction experiments | D29: Michael Faraday | E29: Royal Institution, London | F29: Electromagnetism | G29: induction | H29: Iron ring, coils, galvanometer; moving magnets | I29: Induced current / EMF | J29: Changing magnetic flux induces current | K29: Faraday's law; electromagnetic induction | L29: Basis of generators, transformers, field theory | M29: Encyclopedic overview | N29: https://en.wikipedia.org/wiki/Faraday%27s_law_of_induction | O29: 1
A30: E029 | B30: 1833-1834 | C30: Faraday electrolysis laws | D30: Michael Faraday | E30: Royal Institution, London | F30: Electromagnetism / chemistry physics | G30: electrochemistry | H30: Electrolytic cells and weighed deposits | I30: Mass deposited vs charge | J30: Chemical change proportional to electric charge | K30: Quantization of charge precursor; electrochemistry | L30: Linked electricity with matter quantitatively | M30: Encyclopedic overview | N30: https://en.wikipedia.org/wiki/Faraday%27s_laws_of_electrolysis | O30: 1
A31: E030 | B31: 1840 | C31: Joule's law of heating | D31: James Prescott Joule | E31: Manchester | F31: Thermodynamics / electromagnetism | G31: energy conversion | H31: Current through conductors; calorimetry | I31: Heat vs current, resistance, time | J31: Heat generated is proportional to I²Rt | K31: Energy dissipation in circuits | L31: Foundation of electrical heating and energy conservation | M31: Encyclopedic overview | N31: https://en.wikipedia.org/wiki/Joule_heating | O31: 1
A32: E031 | B32: 1845 | C32: Faraday effect: magnetic rotation of polarization | D32: Michael Faraday | E32: Royal Institution, London | F32: Optics / electromagnetism | G32: magneto-optics | H32: Polarized light through material in magnetic field | I32: Rotation angle of polarization | J32: Magnetic field affects light propagation in matter | K32: Electromagnetic nature of light precursor | L32: First direct link between magnetism and light | M32: Encyclopedic overview | N32: https://en.wikipedia.org/wiki/Faraday_effect | O32: 1
A33: E032 | B33: 1847-1849 | C33: Joule paddle-wheel mechanical equivalent of heat | D33: James Prescott Joule | E33: Manchester | F33: Thermodynamics | G33: energy conservation | H33: Falling weights drive paddles in water | I33: Temperature rise per mechanical work | J33: Mechanical work converts to heat with fixed equivalent | K33: First law of thermodynamics | L33: Landmark in conservation of energy | M33: Encyclopedic overview | N33: https://en.wikipedia.org/wiki/Mechanical_equivalent_of_heat | O33: 1
A34: E033 | B34: 1849 | C34: Fizeau toothed-wheel speed of light measurement | D34: Hippolyte Fizeau | E34: Paris area | F34: Optics | G34: speed of light | H34: T غoothed wheel and distant mirror | I34: Time of flight inferred from wheel speed | J34: Terrestrial measurement of light speed | K34: Finite light speed | L34: First successful terrestrial speed-of-light measurement | M34: Encyclopedic overview | N34: https://en.wikipedia.org/wiki/Fizeau%E2%80%93Foucault_apparatus | O34: 1
A35: E034 | B35: 1851 | C35: Foucault pendulum | D35: Léon Foucault | E35: Paris Panthéon | F35: Classical mechanics / geophysics | G35: rotation | H35: Long pendulum | I35: Precession of oscillation plane | J35: Earth's rotation directly demonstrated | K35: Rotating reference frames | L35: Iconic demonstration of Earth's rotation | M35: Encyclopedic overview | N35: https://en.wikipedia.org/wiki/Foucault_pendulum | O35: 1
A36: E035 | B36: 1851 | C36: Fizeau experiment on light in moving water | D36: Hippolyte Fizeau | E36: Paris | F36: Optics / relativity precursor | G36: light propagation in media | H36: Interferometer with moving water tubes | I36: Fringe shift | J36: Partial dragging of light by moving medium | K36: Fresnel drag coefficient; relativity precursor | L36: Important input for electrodynamics of moving bodies | M36: Encyclopedic overview | N36: https://en.wikipedia.org/wiki/Fizeau_experiment | O36: 1
A37: E036 | B37: 1859-1860 | C37: Kirchhoff-Bunsen spectroscopy experiments | D37: Gustav Kirchhoff; Robert Bunsen | E37: Heidelberg | F37: Optics / atomic physics | G37: spectroscopy | H37: Prism spectroscope and flame spectra | I37: Emission/absorption spectral lines | J37: Elements have characteristic spectra; solar lines explained | K37: Spectral analysis; atomic structure precursor | L37: Founded astrophysical spectroscopy and chemical spectroscopy | M37: Encyclopedic overview | N37: https://en.wikipedia.org/wiki/Emission_spectrum#History | O37: 1
A38: E037 | B38: 1861 | C38: Maxwell color photograph demonstration | D38: James Clerk Maxwell; Thomas Sutton | E38: Royal Institution, London | F38: Optics | G38: color vision | H38: Three-color photographic separations | I38: Additive color reconstruction | J38: Color images can be reconstructed from RGB components | K38: Color theory; electromagnetic optics context | L38: Milestone in color science and imaging | M38: Encyclopedic overview | N38: https://en.wikipedia.org/wiki/Tartan_Ribbon | O38: 3 | P38: Important to optics/imaging, less central to fundamental physics
A39: E038 | B39: 1869 | C39: Andrews critical point of carbon dioxide | D39: Thomas Andrews | E39: Belfast | F39: Thermodynamics | G39: phase transitions | H39: Pressure-volume-temperature measurements of CO₂ | I39: P-V isotherms; critical temperature | J39: Liquid-gas distinction disappears above critical point | K39: Critical phenomena; phase transitions | L39: Foundational for phase diagrams and critical behavior | M39: Encyclopedic overview | N39: https://en.wikipedia.org/wiki/Critical_point_(thermodynamics) | O39: 1
A40: E039 | B40: 1879 | C40: Crookes cathode-ray tube experiments | D40: William Crookes | E40: London | F40: Atomic / plasma physics | G40: cathode rays | H40: Low-pressure discharge tubes | I40: Cathode-ray shadows and fluorescence | J40: Cathode rays travel from cathode and carry momentum-like effects | K40: Electron precursor; discharge physics | L40: Prepared path to electron discovery | M40: Encyclopedic overview | N40: https://en.wikipedia.org/wiki/Crookes_tube | O40: 2
...

Sheet Summary
A1: Catalogue Summary
A3: Metric | B3: Formula / value
A4: Total catalogue rows | B4: =COUNTA(Experiments!A2:A130) -> 129
A5: Earliest numeric start year | B5: =MIN(Experiments!#REF!) -> #REF!
A6: Latest numeric start year | B6: =MAX(Experiments!#REF!) -> #REF!
A7: Tier-1 canonical rows | B7: =COUNTIF(Experiments!O2:O130,1) -> 102
A8: Rows with caveat/notes | B8: 31
A10: Physics branch | B10: Count | C10: Share | E10: Importance tier | F10: Count | G10: Definition
A11: Acoustics / waves | B11: =COUNTIF(Experiments!F$2:F$130,A11) -> 1 | C11: =B11/$B$4 -> 0.007751938 | E11: 1 | F11: =COUNTIF(Experiments!O$2:O$130,E11) -> 102 | G11: Canonical field-shaping experiment/observation
A12: Astronomy / geophysics | B12: =COUNTIF(Experiments!F$2:F$130,A12) -> 1 | C12: =B12/$B$4 -> 0.007751938 | E12: 2 | F12: =COUNTIF(Experiments!O$2:O$130,E12) -> 21 | G12: Very important but more specialized/programmatic
A13: Astronomy / relativity precursor | B13: =COUNTIF(Experiments!F$2:F$130,A13) -> 1 | C13: =B13/$B$4 -> 0.007751938 | E13: 3 | F13: =COUNTIF(Experiments!O$2:O$130,E13) -> 6 | G13: Contextual, instrumental, or theory-linked milestone
A14: Astroparticle physics | B14: =COUNTIF(Experiments!F$2:F$130,A14) -> 3 | C14: =B14/$B$4 -> 0.023255814
A15: Astrophysics | B15: =COUNTIF(Experiments!F$2:F$130,A15) -> 1 | C15: =B15/$B$4 -> 0.007751938
A16: Astrophysics / gravitation | B16: =COUNTIF(Experiments!F$2:F$130,A16) -> 2 | C16: =B16/$B$4 -> 0.015503876 | E16: Period | F16: Count
A17: Astrophysics / nuclear physics | B17: =COUNTIF(Experiments!F$2:F$130,A17) -> 1 | C17: =B17/$B$4 -> 0.007751938 | E17: Ancient–Medieval | F17: =COUNTIFS(Experiments!#REF!,"<1500") -> #REF!
A18: Atomic / condensed matter physics | B18: =COUNTIF(Experiments!F$2:F$130,A18) -> 1 | C18: =B18/$B$4 -> 0.007751938 | E18: Scientific Revolution / Early modern | F18: =COUNTIFS(Experiments!#REF!,">=1500",Experiments!#REF!,"<1800") -> #REF!
A19: Atomic / optical physics | B19: =COUNTIF(Experiments!F$2:F$130,A19) -> 1 | C19: =B19/$B$4 -> 0.007751938 | E19: 19th century | F19: =COUNTIFS(Experiments!#REF!,">=1800",Experiments!#REF!,"<1900") -> #REF!
A20: Atomic / particle physics | B20: =COUNTIF(Experiments!F$2:F$130,A20) -> 1 | C20: =B20/$B$4 -> 0.007751938 | E20: 1900–1945 | F20: =COUNTIFS(Experiments!#REF!,">=1900",Experiments!#REF!,"<=1945") -> #REF!
A21: Atomic / plasma physics | B21: =COUNTIF(Experiments!F$2:F$130,A21) -> 1 | C21: =B21/$B$4 -> 0.007751938 | E21: Postwar 1946–1979 | F21: =COUNTIFS(Experiments!#REF!,">=1946",Experiments!#REF!,"<=1979") -> #REF!
A22: Atomic physics | B22: =COUNTIF(Experiments!F$2:F$130,A22) -> 4 | C22: =B22/$B$4 -> 0.031007752 | E22: 1980–1999 | F22: =COUNTIFS(Experiments!#REF!,">=1980",Experiments!#REF!,"<=1999") -> #REF!
A23: Atomic physics / quantum gases | B23: =COUNTIF(Experiments!F$2:F$130,A23) -> 1 | C23: =B23/$B$4 -> 0.007751938 | E23: 2000–present | F23: =COUNTIFS(Experiments!#REF!,">=2000") -> #REF!
A24: Atomic physics / radiation | B24: =COUNTIF(Experiments!F$2:F$130,A24) -> 1 | C24: =B24/$B$4 -> 0.007751938
A25: Atomic physics / spectroscopy | B25: =COUNTIF(Experiments!F$2:F$130,A25) -> 1 | C25: =B25/$B$4 -> 0.007751938
A26: Classical mechanics | B26: =COUNTIF(Experiments!F$2:F$130,A26) -> 3 | C26: =B26/$B$4 -> 0.023255814
A27: Classical mechanics / geophysics | B27: =COUNTIF(Experiments!F$2:F$130,A27) -> 1 | C27: =B27/$B$4 -> 0.007751938
A28: Condensed matter | B28: =COUNTIF(Experiments!F$2:F$130,A28) -> 6 | C28: =B28/$B$4 -> 0.046511628
A29: Condensed matter / atomic physics | B29: =COUNTIF(Experiments!F$2:F$130,A29) -> 1 | C29: =B29/$B$4 -> 0.007751938
A30: Condensed matter / electromagnetism | B30: =COUNTIF(Experiments!F$2:F$130,A30) -> 2 | C30: =B30/$B$4 -> 0.015503876
A31: Condensed matter / nanophysics | B31: =COUNTIF(Experiments!F$2:F$130,A31) -> 1 | C31: =B31/$B$4 -> 0.007751938
A32: Condensed matter / quantum physics | B32: =COUNTIF(Experiments!F$2:F$130,A32) -> 1 | C32: =B32/$B$4 -> 0.007751938
A33: Cosmology | B33: =COUNTIF(Experiments!F$2:F$130,A33) -> 5 | C33: =B33/$B$4 -> 0.03875969
A34: Electromagnetism | B34: =COUNTIF(Experiments!F$2:F$130,A34) -> 6 | C34: =B34/$B$4 -> 0.046511628
A35: Electromagnetism / chemistry physics | B35: =COUNTIF(Experiments!F$2:F$130,A35) -> 1 | C35: =B35/$B$4 -> 0.007751938
... A71: Thermodynamics / gases | B71: =COUNTIF(Experiments!F$2:F$130,A71) -> 1 | C71: =B71/$B$4 -> 0.007751938

Sheet Bibliography
A1: Reference hub | B1: Use in this workbook | C1: URL
A2: Nobel Prize physics archive | B2: Prize summaries, lectures, and scientific background for Nobel-recognized experiments. | C2: https://www.nobelprize.org/prizes/physics/
A3: American Physical Society history resources | B3: Accessible historical essays and selected primary context. | C3: https://www.aps.org/archives
A4: CERN history and experiment pages | B4: Particle-physics discoveries, detectors, and accelerator history. | C4: https://home.cern/science
A5: NASA astrophysics missions | B5: Mission pages for COBE, WMAP, JWST and related astrophysics data sets. | C5: https://science.nasa.gov/
A6: ESA Planck mission | B6: Planck satellite mission and cosmology outputs. | C6: https://www.esa.int/Science_Exploration/Space_Science/Planck
A7: LIGO Laboratory | B7: Gravitational-wave detections, observatory descriptions, and data releases. | C7: https://www.ligo.caltech.edu/
A8: Event Horizon Telescope | B8: EHT collaboration results and black-hole imaging releases. | C8: https://eventhorizontelescope.org/
A9: Particle Data Group | B9: Authoritative particle properties and review articles. | C9: https://pdg.lbl.gov/
A10: NIST physics laboratory resources | B10: Precision measurement, constants, clocks, and standards context. | C10: https://www.nist.gov/pml
A11: Stanford Encyclopedia of Philosophy | B11: Useful for conceptual foundations and historical-philosophical interpretation. | C11: https://plato.stanford.edu/
A12: Internet Archive / scanned primary works | B12: Useful for historical monographs and original papers in public domain. | C12: https://archive.org/
... A15: Google Scholar | B15: Broad bibliographic follow-up; verify records before citation. | C15: https://scholar.google.com/

Sheet Glossary
A1: Field | B1: Definition / allowed value
A2: Importance tier 1 | B2: Canonical field-shaping experiment/observation; use for central narrative spine.
A3: Importance tier 2 | B3: Highly important, but more specialized, derivative, programmatic, or less universally canonical.
A4: Importance tier 3 | B4: Contextual/theoretical/instrumental milestone included to help interpretation.
A5: Source kind: Encyclopedic overview | B5: A stable orientation URL; should be supplemented by primary literature for publication.
A6: Source kind: Nobel / encyclopedic overview | B6: Nobel pages or Nobel-related context plus an overview URL.
A7: Source kind: Scholarly overview | B7: A page suitable for identifying the relevant primary literature and modern historiography.
A8: Controlled scope | B8: The catalogue includes observations when they served the same evidentiary role as experiments in physics history.
